Workbook

Sheet Raw
A1: Day | B1: Item | C1: Calories | D1: Time
A2: 46202 | B2: Aldi low fat coffee | C2: 140 | D2: 0.52083333
A3: 46202 | B3: Blueberry pack | C3: 250 | D3: 0.52083333
A4: 46202 | B4: Prawn crackers 1/3 pack | C4: 175 | D4: 0.71875
A5: 46202 | B5: Cous cous with 3 eggs | C5: 549 | D5: 0.90625
A6: 46202 | B6: 1/2 dub choc subway cookie | C6: 110 | D6: 0.97152778
A7: 46203 | B7: Aldi iced coffee | C7: 125 | D7: 0.48263889
A8: 46203 | B8: Cous cous + 2 eggs | C8: 484 | D8: 0.57152778
A9: 46203 | B9: Homemade spinach and potato curry w gbread | C9: 907 | D9: 0.78125
A10: 46203 | B10: 1/3 pack prawn crackers | C10: 175 | D10: 0.92916667
A11: 46204 | B11: Spar butter chicken | C11: 1210 | D11: 0.52083333
A12: 46204 | B12: Homemade spinach and potato curry | C12: 629 | D12: 0.84027778
A13: 46205 | B13: Pizza | C13: 1709 | D13: 0.93055556
... A101: 46230 | B101: Protein coffee | C101: 125 | D101: 0.44444444

Sheet Day tracker
A1: Day | B1: Total in | C1: Active out | D1: Total out | E1: Net | F1: Weight in | G1: Weight time | I1: Baseline cals
A2: 46202 | B2: =IF(A2<=TODAY(),SUMIF(Raw!A:A,A2,Raw!C:C),"") -> 1224 | C2: 591 | D2: =IF(A2<=TODAY(),+$I$2+C2,"") -> 2391 | E2: =IF(A2<=TODAY(),B2-D2,"") -> -1167 | F2: 75.9 | G2: 0.97222222 | I2: 1800
A3: 46203 | B3: =IF(A3<=TODAY(),SUMIF(Raw!A:A,A3,Raw!C:C),"") -> 1691 | C3: 593 | D3: =IF(A3<=TODAY(),+$I$2+C3,"") -> 2393 | E3: =IF(A3<=TODAY(),B3-D3,"") -> -702 | F3: 75.4 | G3: 0.80902778
A4: 46204 | B4: =IF(A4<=TODAY(),SUMIF(Raw!A:A,A4,Raw!C:C),"") -> 1839 | C4: 631 | D4: =IF(A4<=TODAY(),+$I$2+C4,"") -> 2431 | E4: =IF(A4<=TODAY(),B4-D4,"") -> -592 | F4: 75.4 | G4: 0.96875
A5: 46205 | B5: =IF(A5<=TODAY(),SUMIF(Raw!A:A,A5,Raw!C:C),"") -> 1709 | C5: 644 | D5: =IF(A5<=TODAY(),+$I$2+C5,"") -> 2444 | E5: =IF(A5<=TODAY(),B5-D5,"") -> -735 | F5: 75.8 | G5: 0.85
A6: 46206 | B6: =IF(A6<=TODAY(),SUMIF(Raw!A:A,A6,Raw!C:C),"") -> 1509 | C6: 713 | D6: =IF(A6<=TODAY(),+$I$2+C6,"") -> 2513 | E6: =IF(A6<=TODAY(),B6-D6,"") -> -1004 | F6: 75.8 | G6: 0.78680556
A7: 46207 | B7: =IF(A7<=TODAY(),SUMIF(Raw!A:A,A7,Raw!C:C),"") -> 1820 | C7: 538 | D7: =IF(A7<=TODAY(),+$I$2+C7,"") -> 2338 | E7: =IF(A7<=TODAY(),B7-D7,"") -> -518 | F7: 75.6 | G7: 0.52986111
A8: 46208 | B8: =IF(A8<=TODAY(),SUMIF(Raw!A:A,A8,Raw!C:C),"") -> 2391 | C8: 648 | D8: =IF(A8<=TODAY(),+$I$2+C8,"") -> 2448 | E8: =IF(A8<=TODAY(),B8-D8,"") -> -57 | F8: 75.9 | G8: 0.99652778
A9: 46209 | B9: =IF(A9<=TODAY(),SUMIF(Raw!A:A,A9,Raw!C:C),"") -> 1323 | C9: 284 | D9: =IF(A9<=TODAY(),+$I$2+C9,"") -> 2084 | E9: =IF(A9<=TODAY(),B9-D9,"") -> -761 | F9: 75.2 | G9: 0.83333333
A10: 46210 | B10: =IF(A10<=TODAY(),SUMIF(Raw!A:A,A10,Raw!C:C),"") -> 889 | C10: 983 | D10: =IF(A10<=TODAY(),+$I$2+C10,"") -> 2783 | E10: =IF(A10<=TODAY(),B10-D10,"") -> -1894 | F10: 74.7 | G10: 0.84722222
A11: 46211 | B11: =IF(A11<=TODAY(),SUMIF(Raw!A:A,A11,Raw!C:C),"") -> 1960 | C11: 310 | D11: =IF(A11<=TODAY(),+$I$2+C11,"") -> 2110 | E11: =IF(A11<=TODAY(),B11-D11,"") -> -150 | F11: 73.7 | G11: 0.32291667
A12: 46212 | B12: =IF(A12<=TODAY(),SUMIF(Raw!A:A,A12,Raw!C:C),"") -> 2169 | C12: 120 | D12: =IF(A12<=TODAY(),+$I$2+C12,"") -> 1920 | E12: =IF(A12<=TODAY(),B12-D12,"") -> 249 | F12: 74 | G12: 19.46
A13: 46213 | B13: =IF(A13<=TODAY(),SUMIF(Raw!A:A,A13,Raw!C:C),"") -> 1208 | C13: 611 | D13: =IF(A13<=TODAY(),+$I$2+C13,"") -> 2411 | E13: =IF(A13<=TODAY(),B13-D13,"") -> -1203 | F13: N/A | G13: N/A
A14: 46214 | B14: =IF(A14<=TODAY(),SUMIF(Raw!A:A,A14,Raw!C:C),"") -> 4278 | C14: 687 | D14: =IF(A14<=TODAY(),+$I$2+C14,"") -> 2487 | E14: =IF(A14<=TODAY(),B14-D14,"") -> 1791 | F14: N/A | G14: N/A
A15: 46215 | B15: =IF(A15<=TODAY(),SUMIF(Raw!A:A,A15,Raw!C:C),"") -> 4093 | C15: 650 | D15: =IF(A15<=TODAY(),+$I$2+C15,"") -> 2450 | E15: =IF(A15<=TODAY(),B15-D15,"") -> 1643 | F15: N/A | G15: N/A
A16: 46216 | B16: =IF(A16<=TODAY(),SUMIF(Raw!A:A,A16,Raw!C:C),"") -> 3368 | C16: 916 | D16: =IF(A16<=TODAY(),+$I$2+C16,"") -> 2716 | E16: =IF(A16<=TODAY(),B16-D16,"") -> 652 | F16: N/A | G16: N/A
A17: 46217 | B17: =IF(A17<=TODAY(),SUMIF(Raw!A:A,A17,Raw!C:C),"") -> 3962 | C17: 453 | D17: =IF(A17<=TODAY(),+$I$2+C17,"") -> 2253 | E17: =IF(A17<=TODAY(),B17-D17,"") -> 1709 | F17: 77.3 | G17: 0.88125
A18: 46218 | B18: =IF(A18<=TODAY(),SUMIF(Raw!A:A,A18,Raw!C:C),"") -> 1114 | C18: 799 | D18: =IF(A18<=TODAY(),+$I$2+C18,"") -> 2599 | E18: =IF(A18<=TODAY(),B18-D18,"") -> -1485 | F18: 76 | G18: 0.54166667
A19: 46219 | B19: =IF(A19<=TODAY(),SUMIF(Raw!A:A,A19,Raw!C:C),"") -> 1094 | C19: 510 | D19: =IF(A19<=TODAY(),+$I$2+C19,"") -> 2310 | E19: =IF(A19<=TODAY(),B19-D19,"") -> -1216 | F19: 74.4 | G19: 0.82638889
A20: 46220 | B20: =IF(A20<=TODAY(),SUMIF(Raw!A:A,A20,Raw!C:C),"") -> 1120 | C20: 477 | D20: =IF(A20<=TODAY(),+$I$2+C20,"") -> 2277 | E20: =IF(A20<=TODAY(),B20-D20,"") -> -1157 | F20: 73.6 | G20: 0.74722222
A21: 46221 | B21: =IF(A21<=TODAY(),SUMIF(Raw!A:A,A21,Raw!C:C),"") -> 1536 | C21: 894 | D21: =IF(A21<=TODAY(),+$I$2+C21,"") -> 2694 | E21: =IF(A21<=TODAY(),B21-D21,"") -> -1158 | F21: 74.6 | G21: 0.95833333
A22: 46222 | B22: =IF(A22<=TODAY(),SUMIF(Raw!A:A,A22,Raw!C:C),"") -> 954 | C22: 350 | D22: =IF(A22<=TODAY(),+$I$2+C22,"") -> 2150 | E22: =IF(A22<=TODAY(),B22-D22,"") -> -1196 | F22: 73.9 | G22: 0.93263889
A23: 46223 | B23: =IF(A23<=TODAY(),SUMIF(Raw!A:A,A23,Raw!C:C),"") -> 1605 | C23: 625 | D23: =IF(A23<=TODAY(),+$I$2+C23,"") -> 2425 | E23: =IF(A23<=TODAY(),B23-D23,"") -> -820 | F23: 73.7 | G23: 0.84375
A24: 46224 | B24: =IF(A24<=TODAY(),SUMIF(Raw!A:A,A24,Raw!C:C),"") -> 1029 | C24: 551 | D24: =IF(A24<=TODAY(),+$I$2+C24,"") -> 2351 | E24: =IF(A24<=TODAY(),B24-D24,"") -> -1322 | F24: 73.1 | G24: 0.94930556
A25: 46225 | B25: =IF(A25<=TODAY(),SUMIF(Raw!A:A,A25,Raw!C:C),"") -> 1333 | C25: 645 | D25: =IF(A25<=TODAY(),+$I$2+C25,"") -> 2445 | E25: =IF(A25<=TODAY(),B25-D25,"") -> -1112 | F25: 71.5 | G25: 0.95833333
A26: 46226 | B26: =IF(A26<=TODAY(),SUMIF(Raw!A:A,A26,Raw!C:C),"") -> 2127 | C26: 536 | D26: =IF(A26<=TODAY(),+$I$2+C26,"") -> 2336 | E26: =IF(A26<=TODAY(),B26-D26,"") -> -209 | F26: 72.9 | G26: 0.91666667
A27: 46227 | B27: =IF(A27<=TODAY(),SUMIF(Raw!A:A,A27,Raw!C:C),"") -> 1330 | C27: 740 | D27: =IF(A27<=TODAY(),+$I$2+C27,"") -> 2540 | E27: =IF(A27<=TODAY(),B27-D27,"") -> -1210 | F27: 72.4 | G27: 0.87986111
A28: 46228 | B28: =IF(A28<=TODAY(),SUMIF(Raw!A:A,A28,Raw!C:C),"") -> 2960 | C28: 545 | D28: =IF(A28<=TODAY(),+$I$2+C28,"") -> 2345 | E28: =IF(A28<=TODAY(),B28-D28,"") -> 615 | F28: 73.3 | G28: 0.98333333
A29: 46229 | B29: =IF(A29<=TODAY(),SUMIF(Raw!A:A,A29,Raw!C:C),"") -> 1326 | C29: 306 | D29: =IF(A29<=TODAY(),+$I$2+C29,"") -> 2106 | E29: =IF(A29<=TODAY(),B29-D29,"") -> -780 | F29: 73.5 | G29: 0.84097222
A30: 46230 | B30: =IF(A30<=TODAY(),SUMIF(Raw!A:A,A30,Raw!C:C),"") -> 125 | D30: =IF(A30<=TODAY(),+$I$2+C30,"") -> 1800 | E30: =IF(A30<=TODAY(),B30-D30,"") -> -1675
A31: 46231 | B31: =IF(A31<=TODAY(),SUMIF(Raw!A:A,A31,Raw!C:C),"") | D31: =IF(A31<=TODAY(),+$I$2+C31,"") | E31: =IF(A31<=TODAY(),B31-D31,"")
A32: 46232 | B32: =IF(A32<=TODAY(),SUMIF(Raw!A:A,A32,Raw!C:C),"") | D32: =IF(A32<=TODAY(),+$I$2+C32,"") | E32: =IF(A32<=TODAY(),B32-D32,"")
A33: 46233 | B33: =IF(A33<=TODAY(),SUMIF(Raw!A:A,A33,Raw!C:C),"") | D33: =IF(A33<=TODAY(),+$I$2+C33,"") | E33: =IF(A33<=TODAY(),B33-D33,"")
A34: 46234 | B34: =IF(A34<=TODAY(),SUMIF(Raw!A:A,A34,Raw!C:C),"") | D34: =IF(A34<=TODAY(),+$I$2+C34,"") | E34: =IF(A34<=TODAY(),B34-D34,"")
A35: 46235 | B35: =IF(A35<=TODAY(),SUMIF(Raw!A:A,A35,Raw!C:C),"") | D35: =IF(A35<=TODAY(),+$I$2+C35,"") | E35: =IF(A35<=TODAY(),B35-D35,"")
A36: 46236 | B36: =IF(A36<=TODAY(),SUMIF(Raw!A:A,A36,Raw!C:C),"") | D36: =IF(A36<=TODAY(),+$I$2+C36,"") | E36: =IF(A36<=TODAY(),B36-D36,"")
A37: 46237 | B37: =IF(A37<=TODAY(),SUMIF(Raw!A:A,A37,Raw!C:C),"") | D37: =IF(A37<=TODAY(),+$I$2+C37,"") | E37: =IF(A37<=TODAY(),B37-D37,"")
A38: 46238 | B38: =IF(A38<=TODAY(),SUMIF(Raw!A:A,A38,Raw!C:C),"") | D38: =IF(A38<=TODAY(),+$I$2+C38,"") | E38: =IF(A38<=TODAY(),B38-D38,"")
A39: 46239 | B39: =IF(A39<=TODAY(),SUMIF(Raw!A:A,A39,Raw!C:C),"") | D39: =IF(A39<=TODAY(),+$I$2+C39,"") | E39: =IF(A39<=TODAY(),B39-D39,"")
A40: 46240 | B40: =IF(A40<=TODAY(),SUMIF(Raw!A:A,A40,Raw!C:C),"") | D40: =IF(A40<=TODAY(),+$I$2+C40,"") | E40: =IF(A40<=TODAY(),B40-D40,"")
...

Sheet Week Tracker
A1: Week number | B1: Total cals | C1: Total net | D1: Goal Met | G1: Goal
A2: Week 1 | B2: =SUM(INDEX('Day tracker'!B:B,(ROW()-ROW($B$2))*7+2): INDEX('Day tracker'!B:B,(ROW()-ROW($B$2))*7+8)) -> 12183 | C2: =SUM(INDEX('Day tracker'!E:E,(ROW()-ROW($C$2))*7+2): INDEX('Day tracker'!E:E,(ROW()-ROW($C$2))*7+8)) -> -4775 | D2: =IF(C2<$G$2,"Yes",IF(C2=0,"","No")) -> Yes | G2: -3850
A3: Week 2 | B3: =SUM(INDEX('Day tracker'!B:B,(ROW()-ROW($B$2))*7+2): INDEX('Day tracker'!B:B,(ROW()-ROW($B$2))*7+8)) -> 15920 | C3: =SUM(INDEX('Day tracker'!E:E,(ROW()-ROW($C$2))*7+2): INDEX('Day tracker'!E:E,(ROW()-ROW($C$2))*7+8)) -> -325 | D3: =IF(C3<$G$2,"Yes",IF(C3=0,"","No")) -> No
A4: Week 3 | B4: =SUM(INDEX('Day tracker'!B:B,(ROW()-ROW($B$2))*7+2): INDEX('Day tracker'!B:B,(ROW()-ROW($B$2))*7+8)) -> 13148 | C4: =SUM(INDEX('Day tracker'!E:E,(ROW()-ROW($C$2))*7+2): INDEX('Day tracker'!E:E,(ROW()-ROW($C$2))*7+8)) -> -3851 | D4: =IF(C4<$G$2,"Yes",IF(C4=0,"","No")) -> Yes | G4: Kilos lost
A5: Week 4 | B5: =SUM(INDEX('Day tracker'!B:B,(ROW()-ROW($B$2))*7+2): INDEX('Day tracker'!B:B,(ROW()-ROW($B$2))*7+8)) -> 11710 | C5: =SUM(INDEX('Day tracker'!E:E,(ROW()-ROW($C$2))*7+2): INDEX('Day tracker'!E:E,(ROW()-ROW($C$2))*7+8)) -> -4838 | D5: =IF(C5<$G$2,"Yes",IF(C5=0,"","No")) -> Yes | G5: =(SUM('Day tracker'!E:E)*(1/7.7))/1000 -> -2.0083117
A6: Week 5 | B6: =SUM(INDEX('Day tracker'!B:B,(ROW()-ROW($B$2))*7+2): INDEX('Day tracker'!B:B,(ROW()-ROW($B$2))*7+8)) -> 125 | C6: =SUM(INDEX('Day tracker'!E:E,(ROW()-ROW($C$2))*7+2): INDEX('Day tracker'!E:E,(ROW()-ROW($C$2))*7+8)) -> -1675 | D6: =IF(C6<$G$2,"Yes",IF(C6=0,"","No")) -> No
A7: Week 6 | B7: =SUM(INDEX('Day tracker'!B:B,(ROW()-ROW($B$2))*7+2): INDEX('Day tracker'!B:B,(ROW()-ROW($B$2))*7+8)) -> 0 | C7: =SUM(INDEX('Day tracker'!E:E,(ROW()-ROW($C$2))*7+2): INDEX('Day tracker'!E:E,(ROW()-ROW($C$2))*7+8)) -> 0 | D7: =IF(C7<$G$2,"Yes",IF(C7=0,"","No"))
A8: Week 7 | B8: =SUM(INDEX('Day tracker'!B:B,(ROW()-ROW($B$2))*7+2): INDEX('Day tracker'!B:B,(ROW()-ROW($B$2))*7+8)) -> 0 | C8: =SUM(INDEX('Day tracker'!E:E,(ROW()-ROW($C$2))*7+2): INDEX('Day tracker'!E:E,(ROW()-ROW($C$2))*7+8)) -> 0 | D8: =IF(C8<$G$2,"Yes",IF(C8=0,"","No"))
A9: Week 8 | B9: =SUM(INDEX('Day tracker'!B:B,(ROW()-ROW($B$2))*7+2): INDEX('Day tracker'!B:B,(ROW()-ROW($B$2))*7+8)) -> 0 | C9: =SUM(INDEX('Day tracker'!E:E,(ROW()-ROW($C$2))*7+2): INDEX('Day tracker'!E:E,(ROW()-ROW($C$2))*7+8)) -> 0 | D9: =IF(C9<$G$2,"Yes",IF(C9=0,"","No"))
A10: Week 9 | B10: =SUM(INDEX('Day tracker'!B:B,(ROW()-ROW($B$2))*7+2): INDEX('Day tracker'!B:B,(ROW()-ROW($B$2))*7+8)) -> 0 | C10: =SUM(INDEX('Day tracker'!E:E,(ROW()-ROW($C$2))*7+2): INDEX('Day tracker'!E:E,(ROW()-ROW($C$2))*7+8)) -> 0 | D10: =IF(C10<$G$2,"Yes",IF(C10=0,"","No"))
A11: Week 10 | B11: =SUM(INDEX('Day tracker'!B:B,(ROW()-ROW($B$2))*7+2): INDEX('Day tracker'!B:B,(ROW()-ROW($B$2))*7+8)) -> 0 | C11: =SUM(INDEX('Day tracker'!E:E,(ROW()-ROW($C$2))*7+2): INDEX('Day tracker'!E:E,(ROW()-ROW($C$2))*7+8)) -> 0 | D11: =IF(C11<$G$2,"Yes",IF(C11=0,"","No"))
A12: Week 11 | B12: =SUM(INDEX('Day tracker'!B:B,(ROW()-ROW($B$2))*7+2): INDEX('Day tracker'!B:B,(ROW()-ROW($B$2))*7+8)) -> 0 | C12: =SUM(INDEX('Day tracker'!E:E,(ROW()-ROW($C$2))*7+2): INDEX('Day tracker'!E:E,(ROW()-ROW($C$2))*7+8)) -> 0 | D12: =IF(C12<$G$2,"Yes",IF(C12=0,"","No"))
A13: Week 12 | B13: =SUM(INDEX('Day tracker'!B:B,(ROW()-ROW($B$2))*7+2): INDEX('Day tracker'!B:B,(ROW()-ROW($B$2))*7+8)) -> 0 | C13: =SUM(INDEX('Day tracker'!E:E,(ROW()-ROW($C$2))*7+2): INDEX('Day tracker'!E:E,(ROW()-ROW($C$2))*7+8)) -> 0 | D13: =IF(C13<$G$2,"Yes",IF(C13=0,"","No"))
A14: Week 13 | B14: =SUM(INDEX('Day tracker'!B:B,(ROW()-ROW($B$2))*7+2): INDEX('Day tracker'!B:B,(ROW()-ROW($B$2))*7+8)) -> 0 | C14: =SUM(INDEX('Day tracker'!E:E,(ROW()-ROW($C$2))*7+2): INDEX('Day tracker'!E:E,(ROW()-ROW($C$2))*7+8)) -> 0 | D14: =IF(C14<$G$2,"Yes",IF(C14=0,"","No"))
A15: Week 14 | B15: =SUM(INDEX('Day tracker'!B:B,(ROW()-ROW($B$2))*7+2): INDEX('Day tracker'!B:B,(ROW()-ROW($B$2))*7+8)) -> 0 | C15: =SUM(INDEX('Day tracker'!E:E,(ROW()-ROW($C$2))*7+2): INDEX('Day tracker'!E:E,(ROW()-ROW($C$2))*7+8)) -> 0 | D15: =IF(C15<$G$2,"Yes",IF(C15=0,"","No"))
A16: Week 15 | B16: =SUM(INDEX('Day tracker'!B:B,(ROW()-ROW($B$2))*7+2): INDEX('Day tracker'!B:B,(ROW()-ROW($B$2))*7+8)) -> 0 | C16: =SUM(INDEX('Day tracker'!E:E,(ROW()-ROW($C$2))*7+2): INDEX('Day tracker'!E:E,(ROW()-ROW($C$2))*7+8)) -> 0 | D16: =IF(C16<$G$2,"Yes",IF(C16=0,"","No"))
A17: Week 16 | B17: =SUM(INDEX('Day tracker'!B:B,(ROW()-ROW($B$2))*7+2): INDEX('Day tracker'!B:B,(ROW()-ROW($B$2))*7+8)) -> 0 | C17: =SUM(INDEX('Day tracker'!E:E,(ROW()-ROW($C$2))*7+2): INDEX('Day tracker'!E:E,(ROW()-ROW($C$2))*7+8)) -> 0 | D17: =IF(C17<$G$2,"Yes",IF(C17=0,"","No"))

Sheet Dashboard
A1: {='Day tracker'!A1:A126} -> Day | B1: {=_xlfn.MAP('Day tracker'!F1:F126, _xlfn.LAMBDA(_xlpm.cell, IF(OR(_xlpm.cell="", _xlpm.cell="N/A", ISNA(_xlpm.cell)), NA(), _xlpm.cell)))} -> Weight in
A2: 46202 | B2: 75.9
A3: 46203 | B3: 75.4
A4: 46204 | B4: 75.4
A5: 46205 | B5: 75.8
A6: 46206 | B6: 75.8
A7: 46207 | B7: 75.6
A8: 46208 | B8: 75.9
A9: 46209 | B9: 75.2
A10: 46210 | B10: 74.7
A11: 46211 | B11: 73.7
A12: 46212 | B12: 74
A13: 46213 | B13: #N/A
A14: 46214 | B14: #N/A
A15: 46215 | B15: #N/A
A16: 46216 | B16: #N/A
A17: 46217 | B17: 77.3
A18: 46218 | B18: 76
A19: 46219 | B19: 74.4
A20: 46220 | B20: 73.6
A21: 46221 | B21: 74.6
A22: 46222 | B22: 73.9
A23: 46223 | B23: 73.7
A24: 46224 | B24: 73.1
A25: 46225 | B25: 71.5
A26: 46226 | B26: 72.9
A27: 46227 | B27: 72.4
A28: 46228 | B28: 73.3
A29: 46229 | B29: 73.5
A30: 46230 | B30: #N/A
A31: 46231 | B31: #N/A
A32: 46232 | B32: #N/A
A33: 46233 | B33: #N/A
A34: 46234 | B34: #N/A
A35: 46235 | B35: #N/A
A36: 46236 | B36: #N/A
A37: 46237 | B37: #N/A
A38: 46238 | B38: #N/A
A39: 46239 | B39: #N/A
A40: 46240 | B40: #N/A
...
